Workbook
Name DashBoard: DashBoard!$A$1:$E$53
Name Payments: Transaction_Log!$A$1:$D$118

Sheet Owner_Master
A1: Villa No | B1: Owner Name | C1: Monthly Rate | D1: Opening Balance (as of Jan-01-2026) | E1: Months Elapsed
A2: D 6 | B2: Balamurugan | C2: 1500 | D2: 0 | E2: 5
A3: C 10 | B3: R.Chetan Kumar | C3: 1500 | D3: 0 | E3: 5
A4: C 14 | B4: Latish Babu | C4: 1500 | D4: 0 | E4: 5
A5: C 18 - 19 | B5: Malathy Sundaram | C5: 1500 | D5: 0 | E5: 5
A6: B 20 - 21 | B6: M .Kalaivani Chandramohan | C6: 1500 | D6: 0 | E6: 5
A7: B 23 | B7: S.V. Sanjeev Kumar | C7: 1500 | D7: 0 | E7: 5
A8: B 27 | B8: S.Rajeswari | C8: 1500 | D8: 0 | E8: 5
A9: A 37 | B9: Bhagath | C9: 1500 | D9: 0 | E9: 5
A10: B 39 | B10: G.Dachinamoorthy & Pinky Moorthy & DP Mohit | C10: 1500 | D10: 0 | E10: 5
A11: B 40 | B11: Raja & Chitra | C11: 1500 | D11: 0 | E11: 5
A12: B 41 - 42 | B12: Sivaramakrishnan | C12: 1500 | D12: 0 | E12: 5
A13: B 69 | B13: Rajesh Babu Krishnan | C13: 1500 | D13: 0 | E13: 5
... A53: B 66 | B53: C.Narayanan | C53: 1500 | D53: -500 | E53: 5
D55: =SUM(Table2[Opening Balance (as of Jan-01-2026)]) -> 475500

Sheet Transaction_Log
A1: Date | B1: Villa No | C1: Amount | D1: Owner
A2: 46023 | B2: C 18 - 19 | C2: 1500 | D2: =VLOOKUP(B2,Owner_Master!$A$1:$B$53,2,FALSE()) -> Malathy Sundaram
A3: 46023 | B3: C 14 | C3: 1500 | D3: =VLOOKUP(B3,Owner_Master!$A$1:$B$53,2,FALSE()) -> Latish Babu
A4: 46023 | B4: B 20 - 21 | C4: 1500 | D4: =VLOOKUP(B4,Owner_Master!$A$1:$B$53,2,FALSE()) -> M .Kalaivani Chandramohan
A5: 46024 | B5: B 22 | C5: 1500 | D5: =VLOOKUP(B5,Owner_Master!$A$1:$B$53,2,FALSE()) -> N.Naveenkumar & G.Mahalakshmi
A6: 46024 | B6: A 37 | C6: 1500 | D6: =VLOOKUP(B6,Owner_Master!$A$1:$B$53,2,FALSE()) -> Bhagath
A7: 46024 | B7: B 69 | C7: 1500 | D7: =VLOOKUP(B7,Owner_Master!$A$1:$B$53,2,FALSE()) -> Rajesh Babu Krishnan
A8: 46025 | B8: C 12 | C8: 3000 | D8: =VLOOKUP(B8,Owner_Master!$A$1:$B$53,2,FALSE()) -> Selvendran Ayyaswamy
A9: 46025 | B9: B 64 | C9: 3000 | D9: =VLOOKUP(B9,Owner_Master!$A$1:$B$53,2,FALSE()) -> Thejaswini & Mahadeva Swamy
A10: 46029 | B10: C 10 | C10: 1500 | D10: =VLOOKUP(B10,Owner_Master!$A$1:$B$53,2,FALSE()) -> R.Chetan Kumar
A11: 46029 | B11: A 38 | C11: 4500 | D11: =VLOOKUP(B11,Owner_Master!$A$1:$B$53,2,FALSE()) -> Manikandan Kumar & Rakeshwari
A12: 46030 | B12: B 45 | C12: 1500 | D12: =VLOOKUP(B12,Owner_Master!$A$1:$B$53,2,FALSE()) -> K. Ramji
A13: 46031 | B13: B 65 | C13: 1500 | D13: =VLOOKUP(B13,Owner_Master!$A$1:$B$53,2,FALSE()) -> K. Suseela
... A124: 46162 | B124: A 54 - 55 | C124: 10500 | D124: =VLOOKUP(B124,Owner_Master!$A$1:$B$53,2,FALSE()) -> P. Rajeev Nair
C135: =SUM(C2:C134) -> 577000

Sheet DashBoard
A1: Villa No | B1: Accrued Charges | C1: Total Paid | D1: Current Status | E1: Status | I1: Summary
A2: D 1 | B2: =VLOOKUP(A2,Owner_Master!A:E,4,0)+(VLOOKUP(A2,Owner_Master!A:E,3,0)*VLOOKUP(A2,Owner_Master!A:E,5,0)) -> 10500 | C2: =SUMIF(Transaction_Log!$B:$B,$A2,Transaction_Log!$C:$C) -> 9000 | D2: =B2-C2 -> 1500 | E2: {=_xlfn.IFS(D2>0, "Arrears", D2<0, "Prepaid", D2=0, "Settled")} -> Arrears | I2: Opening Balance as of 1-Jan-2026 | J2: =+Owner_Master!D55 -> 475500
A3: D 2 | B3: =VLOOKUP(A3,Owner_Master!A:E,4,0)+(VLOOKUP(A3,Owner_Master!A:E,3,0)*VLOOKUP(A3,Owner_Master!A:E,5,0)) -> 9000 | C3: =SUMIF(Transaction_Log!$B:$B,$A3,Transaction_Log!$C:$C) -> 6000 | D3: =B3-C3 -> 3000 | E3: {=_xlfn.IFS(D3>0, "Arrears", D3<0, "Prepaid", D3=0, "Settled")} -> Arrears | I3: Maintenance charges - Jan-May 2026 | J3: =78000*5 -> 390000
A4: D 3 | B4: =VLOOKUP(A4,Owner_Master!A:E,4,0)+(VLOOKUP(A4,Owner_Master!A:E,3,0)*VLOOKUP(A4,Owner_Master!A:E,5,0)) -> 9000 | C4: =SUMIF(Transaction_Log!$B:$B,$A4,Transaction_Log!$C:$C) -> 6000 | D4: =B4-C4 -> 3000 | E4: {=_xlfn.IFS(D4>0, "Arrears", D4<0, "Prepaid", D4=0, "Settled")} -> Arrears | J4: =+J3+J2 -> 865500
A5: D 4 | B5: =VLOOKUP(A5,Owner_Master!A:E,4,0)+(VLOOKUP(A5,Owner_Master!A:E,3,0)*VLOOKUP(A5,Owner_Master!A:E,5,0)) -> 1500 | C5: =SUMIF(Transaction_Log!$B:$B,$A5,Transaction_Log!$C:$C) -> 18000 | D5: =B5-C5 -> -16500 | E5: {=_xlfn.IFS(D5>0, "Arrears", D5<0, "Prepaid", D5=0, "Settled")} -> Prepaid
A6: D 5 | B6: =VLOOKUP(A6,Owner_Master!A:E,4,0)+(VLOOKUP(A6,Owner_Master!A:E,3,0)*VLOOKUP(A6,Owner_Master!A:E,5,0)) -> 22500 | C6: =SUMIF(Transaction_Log!$B:$B,$A6,Transaction_Log!$C:$C) -> 0 | D6: =B6-C6 -> 22500 | E6: {=_xlfn.IFS(D6>0, "Arrears", D6<0, "Prepaid", D6=0, "Settled")} -> Arrears | I6: Payments received until 16th May 2026 | J6: =+Transaction_Log!C135 -> 577000
A7: D 6 | B7: =VLOOKUP(A7,Owner_Master!A:E,4,0)+(VLOOKUP(A7,Owner_Master!A:E,3,0)*VLOOKUP(A7,Owner_Master!A:E,5,0)) -> 7500 | C7: =SUMIF(Transaction_Log!$B:$B,$A7,Transaction_Log!$C:$C) -> 3000 | D7: =B7-C7 -> 4500 | E7: {=_xlfn.IFS(D7>0, "Arrears", D7<0, "Prepaid", D7=0, "Settled")} -> Arrears
A8: D 7 | B8: =VLOOKUP(A8,Owner_Master!A:E,4,0)+(VLOOKUP(A8,Owner_Master!A:E,3,0)*VLOOKUP(A8,Owner_Master!A:E,5,0)) -> 24000 | C8: =SUMIF(Transaction_Log!$B:$B,$A8,Transaction_Log!$C:$C) -> 18000 | D8: =B8-C8 -> 6000 | E8: {=_xlfn.IFS(D8>0, "Arrears", D8<0, "Prepaid", D8=0, "Settled")} -> Arrears | I8: Balance outstanding as of 12th May 2026 | J8: =+J4-J6 -> 288500
A9: D 9 | B9: =VLOOKUP(A9,Owner_Master!A:E,4,0)+(VLOOKUP(A9,Owner_Master!A:E,3,0)*VLOOKUP(A9,Owner_Master!A:E,5,0)) -> 6000 | C9: =SUMIF(Transaction_Log!$B:$B,$A9,Transaction_Log!$C:$C) -> 6000 | D9: =B9-C9 -> 0 | E9: {=_xlfn.IFS(D9>0, "Arrears", D9<0, "Prepaid", D9=0, "Settled")} -> Settled
A10: C 10 | B10: =VLOOKUP(A10,Owner_Master!A:E,4,0)+(VLOOKUP(A10,Owner_Master!A:E,3,0)*VLOOKUP(A10,Owner_Master!A:E,5,0)) -> 7500 | C10: =SUMIF(Transaction_Log!$B:$B,$A10,Transaction_Log!$C:$C) -> 7500 | D10: =B10-C10 -> 0 | E10: {=_xlfn.IFS(D10>0, "Arrears", D10<0, "Prepaid", D10=0, "Settled")} -> Settled
A11: C 11 | B11: =VLOOKUP(A11,Owner_Master!A:E,4,0)+(VLOOKUP(A11,Owner_Master!A:E,3,0)*VLOOKUP(A11,Owner_Master!A:E,5,0)) -> 39000 | C11: =SUMIF(Transaction_Log!$B:$B,$A11,Transaction_Log!$C:$C) -> 31000 | D11: =B11-C11 -> 8000 | E11: {=_xlfn.IFS(D11>0, "Arrears", D11<0, "Prepaid", D11=0, "Settled")} -> Arrears
A12: C 12 | B12: =VLOOKUP(A12,Owner_Master!A:E,4,0)+(VLOOKUP(A12,Owner_Master!A:E,3,0)*VLOOKUP(A12,Owner_Master!A:E,5,0)) -> 9000 | C12: =SUMIF(Transaction_Log!$B:$B,$A12,Transaction_Log!$C:$C) -> 9000 | D12: =B12-C12 -> 0 | E12: {=_xlfn.IFS(D12>0, "Arrears", D12<0, "Prepaid", D12=0, "Settled")} -> Settled
A13: C 14 | B13: =VLOOKUP(A13,Owner_Master!A:E,4,0)+(VLOOKUP(A13,Owner_Master!A:E,3,0)*VLOOKUP(A13,Owner_Master!A:E,5,0)) -> 7500 | C13: =SUMIF(Transaction_Log!$B:$B,$A13,Transaction_Log!$C:$C) -> 6000 | D13: =B13-C13 -> 1500 | E13: {=_xlfn.IFS(D13>0, "Arrears", D13<0, "Prepaid", D13=0, "Settled")} -> Arrears
A14: C 15 | B14: =VLOOKUP(A14,Owner_Master!A:E,4,0)+(VLOOKUP(A14,Owner_Master!A:E,3,0)*VLOOKUP(A14,Owner_Master!A:E,5,0)) -> 18500 | C14: =SUMIF(Transaction_Log!$B:$B,$A14,Transaction_Log!$C:$C) -> 24500 | D14: =B14-C14 -> -6000 | E14: {=_xlfn.IFS(D14>0, "Arrears", D14<0, "Prepaid", D14=0, "Settled")} -> Prepaid
A15: C 16 | B15: =VLOOKUP(A15,Owner_Master!A:E,4,0)+(VLOOKUP(A15,Owner_Master!A:E,3,0)*VLOOKUP(A15,Owner_Master!A:E,5,0)) -> 22500 | C15: =SUMIF(Transaction_Log!$B:$B,$A15,Transaction_Log!$C:$C) -> 22500 | D15: =B15-C15 -> 0 | E15: {=_xlfn.IFS(D15>0, "Arrears", D15<0, "Prepaid", D15=0, "Settled")} -> Settled
A16: C 18 - 19 | B16: =VLOOKUP(A16,Owner_Master!A:E,4,0)+(VLOOKUP(A16,Owner_Master!A:E,3,0)*VLOOKUP(A16,Owner_Master!A:E,5,0)) -> 7500 | C16: =SUMIF(Transaction_Log!$B:$B,$A16,Transaction_Log!$C:$C) -> 7500 | D16: =B16-C16 -> 0 | E16: {=_xlfn.IFS(D16>0, "Arrears", D16<0, "Prepaid", D16=0, "Settled")} -> Settled
A17: B 20 - 21 | B17: =VLOOKUP(A17,Owner_Master!A:E,4,0)+(VLOOKUP(A17,Owner_Master!A:E,3,0)*VLOOKUP(A17,Owner_Master!A:E,5,0)) -> 7500 | C17: =SUMIF(Transaction_Log!$B:$B,$A17,Transaction_Log!$C:$C) -> 7500 | D17: =B17-C17 -> 0 | E17: {=_xlfn.IFS(D17>0, "Arrears", D17<0, "Prepaid", D17=0, "Settled")} -> Settled
A18: B 22 | B18: =VLOOKUP(A18,Owner_Master!A:E,4,0)+(VLOOKUP(A18,Owner_Master!A:E,3,0)*VLOOKUP(A18,Owner_Master!A:E,5,0)) -> 10500 | C18: =SUMIF(Transaction_Log!$B:$B,$A18,Transaction_Log!$C:$C) -> 7500 | D18: =B18-C18 -> 3000 | E18: {=_xlfn.IFS(D18>0, "Arrears", D18<0, "Prepaid", D18=0, "Settled")} -> Arrears
A19: B 23 | B19: =VLOOKUP(A19,Owner_Master!A:E,4,0)+(VLOOKUP(A19,Owner_Master!A:E,3,0)*VLOOKUP(A19,Owner_Master!A:E,5,0)) -> 7500 | C19: =SUMIF(Transaction_Log!$B:$B,$A19,Transaction_Log!$C:$C) -> 3000 | D19: =B19-C19 -> 4500 | E19: {=_xlfn.IFS(D19>0, "Arrears", D19<0, "Prepaid", D19=0, "Settled")} -> Arrears
A20: B 24 | B20: =VLOOKUP(A20,Owner_Master!A:E,4,0)+(VLOOKUP(A20,Owner_Master!A:E,3,0)*VLOOKUP(A20,Owner_Master!A:E,5,0)) -> 24000 | C20: =SUMIF(Transaction_Log!$B:$B,$A20,Transaction_Log!$C:$C) -> 24000 | D20: =B20-C20 -> 0 | E20: {=_xlfn.IFS(D20>0, "Arrears", D20<0, "Prepaid", D20=0, "Settled")} -> Settled
... A53: B 72 | B53: =VLOOKUP(A53,Owner_Master!A:E,4,0)+(VLOOKUP(A53,Owner_Master!A:E,3,0)*VLOOKUP(A53,Owner_Master!A:E,5,0)) -> 9000 | C53: =SUMIF(Transaction_Log!$B:$B,$A53,Transaction_Log!$C:$C) -> 9000 | D53: =B53-C53 -> 0 | E53: {=_xlfn.IFS(D53>0, "Arrears", D53<0, "Prepaid", D53=0, "Settled")} -> Settled
B56: =SUM(Table3[Accrued Charges]) -> 865500 | C56: =SUM(Table3[Total Paid]) -> 577000 | D56: =SUM(Table3[[Current Status ]]) -> 288500

Sheet Owner_Summary
A1: Payments Consolidated by Owner — Jan to May 2026 | P1: Total
A2: Villa No | B2: Owner Name | C2: 46023 | D2: 46054 | E2: 46082 | F2: 46113 | G2: 46143 | H2: 46174 | I2: 46204 | J2: 46235 | K2: 46266 | L2: 46296 | M2: 46327 | N2: 46357 | O2: Total payments | P2: Outstanding
A3: D 1 | B3: =VLOOKUP($A3,Owner_Master!$A:$B,2,FALSE) -> D. Abhimanyu & Amrutha Abhimanyu | C3: =SUMIFS(Transaction_Log!$C:$C, Transaction_Log!$B:$B, $A3, Transaction_Log!$A:$A, ">="&DATE(2026,1,1), Transaction_Log!$A:$A, "<="&DATE(2026,1,31)) -> 3000 | D3: =SUMIFS(Transaction_Log!$C:$C, Transaction_Log!$B:$B, $A3, Transaction_Log!$A:$A, ">="&DATE(2026,2,1), Transaction_Log!$A:$A, "<="&DATE(2026,2,28)) -> 3000 | E3: =SUMIFS(Transaction_Log!$C:$C, Transaction_Log!$B:$B, $A3, Transaction_Log!$A:$A, ">="&DATE(2026,3,1), Transaction_Log!$A:$A, "<="&DATE(2026,3,31)) -> 0 | F3: =SUMIFS(Transaction_Log!$C:$C, Transaction_Log!$B:$B, $A3, Transaction_Log!$A:$A, ">="&DATE(2026,4,1), Transaction_Log!$A:$A, "<="&DATE(2026,4,30)) -> 3000 | G3: =SUMIFS(Transaction_Log!$C:$C, Transaction_Log!$B:$B, $A3, Transaction_Log!$A:$A, ">="&DATE(2026,5,1), Transaction_Log!$A:$A, "<="&DATE(2026,5,31)) -> 0 | H3: =SUMIFS(Transaction_Log!$C:$C, Transaction_Log!$B:$B, $A3, Transaction_Log!$A:$A, ">="&DATE(2026,6,1), Transaction_Log!$A:$A, "<="&DATE(2026,6,30)) -> 0 | I3: =SUMIFS(Transaction_Log!$C:$C, Transaction_Log!$B:$B, $A3, Transaction_Log!$A:$A, ">="&DATE(2026,7,1), Transaction_Log!$A:$A, "<="&DATE(2026,7,31)) -> 0 | J3: =SUMIFS(Transaction_Log!$C:$C, Transaction_Log!$B:$B, $A3, Transaction_Log!$A:$A, ">="&DATE(2026,8,1), Transaction_Log!$A:$A, "<="&DATE(2026,8,31)) -> 0 | K3: =SUMIFS(Transaction_Log!$C:$C, Transaction_Log!$B:$B, $A3, Transaction_Log!$A:$A, ">="&DATE(2026,9,1), Transaction_Log!$A:$A, "<="&DATE(2026,9,30)) -> 0 | L3: =SUMIFS(Transaction_Log!$C:$C, Transaction_Log!$B:$B, $A3, Transaction_Log!$A:$A, ">="&DATE(2026,10,1), Transaction_Log!$A:$A, "<="&DATE(2026,10,31)) -> 0 | M3: =SUMIFS(Transaction_Log!$C:$C, Transaction_Log!$B:$B, $A3, Transaction_Log!$A:$A, ">="&DATE(2026,11,1), Transaction_Log!$A:$A, "<="&DATE(2026,11,30)) -> 0 | N3: =SUMIFS(Transaction_Log!$C:$C, Transaction_Log!$B:$B, $A3, Transaction_Log!$A:$A, ">="&DATE(2026,12,1), Transaction_Log!$A:$A, "<="&DATE(2026,12,31)) -> 0 | O3: =SUM(C3:N3) -> 9000 | P3: =+DashBoard!D2 -> 1500
A4: D 2 | B4: =VLOOKUP($A4,Owner_Master!$A:$B,2,FALSE) -> Shyamala Krishnan | C4: =SUMIFS(Transaction_Log!$C:$C, Transaction_Log!$B:$B, $A4, Transaction_Log!$A:$A, ">="&DATE(2026,1,1), Transaction_Log!$A:$A, "<="&DATE(2026,1,31)) -> 1500 | D4: =SUMIFS(Transaction_Log!$C:$C, Transaction_Log!$B:$B, $A4, Transaction_Log!$A:$A, ">="&DATE(2026,2,1), Transaction_Log!$A:$A, "<="&DATE(2026,2,28)) -> 0 | E4: =SUMIFS(Transaction_Log!$C:$C, Transaction_Log!$B:$B, $A4, Transaction_Log!$A:$A, ">="&DATE(2026,3,1), Transaction_Log!$A:$A, "<="&DATE(2026,3,31)) -> 4500 | F4: =SUMIFS(Transaction_Log!$C:$C, Transaction_Log!$B:$B, $A4, Transaction_Log!$A:$A, ">="&DATE(2026,4,1), Transaction_Log!$A:$A, "<="&DATE(2026,4,30)) -> 0 | G4: =SUMIFS(Transaction_Log!$C:$C, Transaction_Log!$B:$B, $A4, Transaction_Log!$A:$A, ">="&DATE(2026,5,1), Transaction_Log!$A:$A, "<="&DATE(2026,5,31)) -> 0 | H4: =SUMIFS(Transaction_Log!$C:$C, Transaction_Log!$B:$B, $A4, Transaction_Log!$A:$A, ">="&DATE(2026,6,1), Transaction_Log!$A:$A, "<="&DATE(2026,6,30)) -> 0 | I4: =SUMIFS(Transaction_Log!$C:$C, Transaction_Log!$B:$B, $A4, Transaction_Log!$A:$A, ">="&DATE(2026,7,1), Transaction_Log!$A:$A, "<="&DATE(2026,7,31)) -> 0 | J4: =SUMIFS(Transaction_Log!$C:$C, Transaction_Log!$B:$B, $A4, Transaction_Log!$A:$A, ">="&DATE(2026,8,1), Transaction_Log!$A:$A, "<="&DATE(2026,8,31)) -> 0 | K4: =SUMIFS(Transaction_Log!$C:$C, Transaction_Log!$B:$B, $A4, Transaction_Log!$A:$A, ">="&DATE(2026,9,1), Transaction_Log!$A:$A, "<="&DATE(2026,9,30)) -> 0 | L4: =SUMIFS(Transaction_Log!$C:$C, Transaction_Log!$B:$B, $A4, Transaction_Log!$A:$A, ">="&DATE(2026,10,1), Transaction_Log!$A:$A, "<="&DATE(2026,10,31)) -> 0 | M4: =SUMIFS(Transaction_Log!$C:$C, Transaction_Log!$B:$B, $A4, Transaction_Log!$A:$A, ">="&DATE(2026,11,1), Transaction_Log!$A:$A, "<="&DATE(2026,11,30)) -> 0 | N4: =SUMIFS(Transaction_Log!$C:$C, Transaction_Log!$B:$B, $A4, Transaction_Log!$A:$A, ">="&DATE(2026,12,1), Transaction_Log!$A:$A, "<="&DATE(2026,12,31)) -> 0 | O4: =SUM(C4:N4) -> 6000 | P4: =+DashBoard!D3 -> 3000
A5: D 3 | B5: =VLOOKUP($A5,Owner_Master!$A:$B,2,FALSE) -> Aishwarya Anandanathan | C5: =SUMIFS(Transaction_Log!$C:$C, Transaction_Log!$B:$B, $A5, Transaction_Log!$A:$A, ">="&DATE(2026,1,1), Transaction_Log!$A:$A, "<="&DATE(2026,1,31)) -> 0 | D5: =SUMIFS(Transaction_Log!$C:$C, Transaction_Log!$B:$B, $A5, Transaction_Log!$A:$A, ">="&DATE(2026,2,1), Transaction_Log!$A:$A, "<="&DATE(2026,2,28)) -> 0 | E5: =SUMIFS(Transaction_Log!$C:$C, Transaction_Log!$B:$B, $A5, Transaction_Log!$A:$A, ">="&DATE(2026,3,1), Transaction_Log!$A:$A, "<="&DATE(2026,3,31)) -> 6000 | F5: =SUMIFS(Transaction_Log!$C:$C, Transaction_Log!$B:$B, $A5, Transaction_Log!$A:$A, ">="&DATE(2026,4,1), Transaction_Log!$A:$A, "<="&DATE(2026,4,30)) -> 0 | G5: =SUMIFS(Transaction_Log!$C:$C, Transaction_Log!$B:$B, $A5, Transaction_Log!$A:$A, ">="&DATE(2026,5,1), Transaction_Log!$A:$A, "<="&DATE(2026,5,31)) -> 0 | H5: =SUMIFS(Transaction_Log!$C:$C, Transaction_Log!$B:$B, $A5, Transaction_Log!$A:$A, ">="&DATE(2026,6,1), Transaction_Log!$A:$A, "<="&DATE(2026,6,30)) -> 0 | I5: =SUMIFS(Transaction_Log!$C:$C, Transaction_Log!$B:$B, $A5, Transaction_Log!$A:$A, ">="&DATE(2026,7,1), Transaction_Log!$A:$A, "<="&DATE(2026,7,31)) -> 0 | J5: =SUMIFS(Transaction_Log!$C:$C, Transaction_Log!$B:$B, $A5, Transaction_Log!$A:$A, ">="&DATE(2026,8,1), Transaction_Log!$A:$A, "<="&DATE(2026,8,31)) -> 0 | K5: =SUMIFS(Transaction_Log!$C:$C, Transaction_Log!$B:$B, $A5, Transaction_Log!$A:$A, ">="&DATE(2026,9,1), Transaction_Log!$A:$A, "<="&DATE(2026,9,30)) -> 0 | L5: =SUMIFS(Transaction_Log!$C:$C, Transaction_Log!$B:$B, $A5, Transaction_Log!$A:$A, ">="&DATE(2026,10,1), Transaction_Log!$A:$A, "<="&DATE(2026,10,31)) -> 0 | M5: =SUMIFS(Transaction_Log!$C:$C, Transaction_Log!$B:$B, $A5, Transaction_Log!$A:$A, ">="&DATE(2026,11,1), Transaction_Log!$A:$A, "<="&DATE(2026,11,30)) -> 0 | N5: =SUMIFS(Transaction_Log!$C:$C, Transaction_Log!$B:$B, $A5, Transaction_Log!$A:$A, ">="&DATE(2026,12,1), Transaction_Log!$A:$A, "<="&DATE(2026,12,31)) -> 0 | O5: =SUM(C5:N5) -> 6000 | P5: =+DashBoard!D4 -> 3000
A6: D 4 | B6: =VLOOKUP($A6,Owner_Master!$A:$B,2,FALSE) -> Vishwanath Mohan | C6: =SUMIFS(Transaction_Log!$C:$C, Transaction_Log!$B:$B, $A6, Transaction_Log!$A:$A, ">="&DATE(2026,1,1), Transaction_Log!$A:$A, "<="&DATE(2026,1,31)) -> 0 | D6: =SUMIFS(Transaction_Log!$C:$C, Transaction_Log!$B:$B, $A6, Transaction_Log!$A:$A, ">="&DATE(2026,2,1), Transaction_Log!$A:$A, "<="&DATE(2026,2,28)) -> 0 | E6: =SUMIFS(Transaction_Log!$C:$C, Transaction_Log!$B:$B, $A6, Transaction_Log!$A:$A, ">="&DATE(2026,3,1), Transaction_Log!$A:$A, "<="&DATE(2026,3,31)) -> 0 | F6: =SUMIFS(Transaction_Log!$C:$C, Transaction_Log!$B:$B, $A6, Transaction_Log!$A:$A, ">="&DATE(2026,4,1), Transaction_Log!$A:$A, "<="&DATE(2026,4,30)) -> 0 | G6: =SUMIFS(Transaction_Log!$C:$C, Transaction_Log!$B:$B, $A6, Transaction_Log!$A:$A, ">="&DATE(2026,5,1), Transaction_Log!$A:$A, "<="&DATE(2026,5,31)) -> 18000 | H6: =SUMIFS(Transaction_Log!$C:$C, Transaction_Log!$B:$B, $A6, Transaction_Log!$A:$A, ">="&DATE(2026,6,1), Transaction_Log!$A:$A, "<="&DATE(2026,6,30)) -> 0 | I6: =SUMIFS(Transaction_Log!$C:$C, Transaction_Log!$B:$B, $A6, Transaction_Log!$A:$A, ">="&DATE(2026,7,1), Transaction_Log!$A:$A, "<="&DATE(2026,7,31)) -> 0 | J6: =SUMIFS(Transaction_Log!$C:$C, Transaction_Log!$B:$B, $A6, Transaction_Log!$A:$A, ">="&DATE(2026,8,1), Transaction_Log!$A:$A, "<="&DATE(2026,8,31)) -> 0 | K6: =SUMIFS(Transaction_Log!$C:$C, Transaction_Log!$B:$B, $A6, Transaction_Log!$A:$A, ">="&DATE(2026,9,1), Transaction_Log!$A:$A, "<="&DATE(2026,9,30)) -> 0 | L6: =SUMIFS(Transaction_Log!$C:$C, Transaction_Log!$B:$B, $A6, Transaction_Log!$A:$A, ">="&DATE(2026,10,1), Transaction_Log!$A:$A, "<="&DATE(2026,10,31)) -> 0 | M6: =SUMIFS(Transaction_Log!$C:$C, Transaction_Log!$B:$B, $A6, Transaction_Log!$A:$A, ">="&DATE(2026,11,1), Transaction_Log!$A:$A, "<="&DATE(2026,11,30)) -> 0 | N6: =SUMIFS(Transaction_Log!$C:$C, Transaction_Log!$B:$B, $A6, Transaction_Log!$A:$A, ">="&DATE(2026,12,1), Transaction_Log!$A:$A, "<="&DATE(2026,12,31)) -> 0 | O6: =SUM(C6:N6) -> 18000 | P6: =+DashBoard!D5 -> -16500
A7: D 5 | B7: =VLOOKUP($A7,Owner_Master!$A:$B,2,FALSE) -> S. Shanthi | C7: =SUMIFS(Transaction_Log!$C:$C, Transaction_Log!$B:$B, $A7, Transaction_Log!$A:$A, ">="&DATE(2026,1,1), Transaction_Log!$A:$A, "<="&DATE(2026,1,31)) -> 0 | D7: =SUMIFS(Transaction_Log!$C:$C, Transaction_Log!$B:$B, $A7, Transaction_Log!$A:$A, ">="&DATE(2026,2,1), Transaction_Log!$A:$A, "<="&DATE(2026,2,28)) -> 0 | E7: =SUMIFS(Transaction_Log!$C:$C, Transaction_Log!$B:$B, $A7, Transaction_Log!$A:$A, ">="&DATE(2026,3,1), Transaction_Log!$A:$A, "<="&DATE(2026,3,31)) -> 0 | F7: =SUMIFS(Transaction_Log!$C:$C, Transaction_Log!$B:$B, $A7, Transaction_Log!$A:$A, ">="&DATE(2026,4,1), Transaction_Log!$A:$A, "<="&DATE(2026,4,30)) -> 0 | G7: =SUMIFS(Transaction_Log!$C:$C, Transaction_Log!$B:$B, $A7, Transaction_Log!$A:$A, ">="&DATE(2026,5,1), Transaction_Log!$A:$A, "<="&DATE(2026,5,31)) -> 0 | H7: =SUMIFS(Transaction_Log!$C:$C, Transaction_Log!$B:$B, $A7, Transaction_Log!$A:$A, ">="&DATE(2026,6,1), Transaction_Log!$A:$A, "<="&DATE(2026,6,30)) -> 0 | I7: =SUMIFS(Transaction_Log!$C:$C, Transaction_Log!$B:$B, $A7, Transaction_Log!$A:$A, ">="&DATE(2026,7,1), Transaction_Log!$A:$A, "<="&DATE(2026,7,31)) -> 0 | J7: =SUMIFS(Transaction_Log!$C:$C, Transaction_Log!$B:$B, $A7, Transaction_Log!$A:$A, ">="&DATE(2026,8,1), Transaction_Log!$A:$A, "<="&DATE(2026,8,31)) -> 0 | K7: =SUMIFS(Transaction_Log!$C:$C, Transaction_Log!$B:$B, $A7, Transaction_Log!$A:$A, ">="&DATE(2026,9,1), Transaction_Log!$A:$A, "<="&DATE(2026,9,30)) -> 0 | L7: =SUMIFS(Transaction_Log!$C:$C, Transaction_Log!$B:$B, $A7, Transaction_Log!$A:$A, ">="&DATE(2026,10,1), Transaction_Log!$A:$A, "<="&DATE(2026,10,31)) -> 0 | M7: =SUMIFS(Transaction_Log!$C:$C, Transaction_Log!$B:$B, $A7, Transaction_Log!$A:$A, ">="&DATE(2026,11,1), Transaction_Log!$A:$A, "<="&DATE(2026,11,30)) -> 0 | N7: =SUMIFS(Transaction_Log!$C:$C, Transaction_Log!$B:$B, $A7, Transaction_Log!$A:$A, ">="&DATE(2026,12,1), Transaction_Log!$A:$A, "<="&DATE(2026,12,31)) -> 0 | O7: =SUM(C7:N7) -> 0 | P7: =+DashBoard!D6 -> 22500
A8: D 6 | B8: Subadra & Thirumudi | C8: =SUMIFS(Transaction_Log!$C:$C, Transaction_Log!$B:$B, $A8, Transaction_Log!$A:$A, ">="&DATE(2026,1,1), Transaction_Log!$A:$A, "<="&DATE(2026,1,31)) -> 1500 | D8: =SUMIFS(Transaction_Log!$C:$C, Transaction_Log!$B:$B, $A8, Transaction_Log!$A:$A, ">="&DATE(2026,2,1), Transaction_Log!$A:$A, "<="&DATE(2026,2,28)) -> 1500 | E8: =SUMIFS(Transaction_Log!$C:$C, Transaction_Log!$B:$B, $A8, Transaction_Log!$A:$A, ">="&DATE(2026,3,1), Transaction_Log!$A:$A, "<="&DATE(2026,3,31)) -> 0 | F8: =SUMIFS(Transaction_Log!$C:$C, Transaction_Log!$B:$B, $A8, Transaction_Log!$A:$A, ">="&DATE(2026,4,1), Transaction_Log!$A:$A, "<="&DATE(2026,4,30)) -> 0 | G8: =SUMIFS(Transaction_Log!$C:$C, Transaction_Log!$B:$B, $A8, Transaction_Log!$A:$A, ">="&DATE(2026,5,1), Transaction_Log!$A:$A, "<="&DATE(2026,5,31)) -> 0 | H8: =SUMIFS(Transaction_Log!$C:$C, Transaction_Log!$B:$B, $A8, Transaction_Log!$A:$A, ">="&DATE(2026,6,1), Transaction_Log!$A:$A, "<="&DATE(2026,6,30)) -> 0 | I8: =SUMIFS(Transaction_Log!$C:$C, Transaction_Log!$B:$B, $A8, Transaction_Log!$A:$A, ">="&DATE(2026,7,1), Transaction_Log!$A:$A, "<="&DATE(2026,7,31)) -> 0 | J8: =SUMIFS(Transaction_Log!$C:$C, Transaction_Log!$B:$B, $A8, Transaction_Log!$A:$A, ">="&DATE(2026,8,1), Transaction_Log!$A:$A, "<="&DATE(2026,8,31)) -> 0 | K8: =SUMIFS(Transaction_Log!$C:$C, Transaction_Log!$B:$B, $A8, Transaction_Log!$A:$A, ">="&DATE(2026,9,1), Transaction_Log!$A:$A, "<="&DATE(2026,9,30)) -> 0 | L8: =SUMIFS(Transaction_Log!$C:$C, Transaction_Log!$B:$B, $A8, Transaction_Log!$A:$A, ">="&DATE(2026,10,1), Transaction_Log!$A:$A, "<="&DATE(2026,10,31)) -> 0 | M8: =SUMIFS(Transaction_Log!$C:$C, Transaction_Log!$B:$B, $A8, Transaction_Log!$A:$A, ">="&DATE(2026,11,1), Transaction_Log!$A:$A, "<="&DATE(2026,11,30)) -> 0 | N8: =SUMIFS(Transaction_Log!$C:$C, Transaction_Log!$B:$B, $A8, Transaction_Log!$A:$A, ">="&DATE(2026,12,1), Transaction_Log!$A:$A, "<="&DATE(2026,12,31)) -> 0 | O8: =SUM(C8:N8) -> 3000 | P8: =+DashBoard!D7 -> 4500
A9: D 7 | B9: =VLOOKUP($A9,Owner_Master!$A:$B,2,FALSE) -> Dr. P.S. Balamurugavel | C9: =SUMIFS(Transaction_Log!$C:$C, Transaction_Log!$B:$B, $A9, Transaction_Log!$A:$A, ">="&DATE(2026,1,1), Transaction_Log!$A:$A, "<="&DATE(2026,1,31)) -> 0 | D9: =SUMIFS(Transaction_Log!$C:$C, Transaction_Log!$B:$B, $A9, Transaction_Log!$A:$A, ">="&DATE(2026,2,1), Transaction_Log!$A:$A, "<="&DATE(2026,2,28)) -> 0 | E9: =SUMIFS(Transaction_Log!$C:$C, Transaction_Log!$B:$B, $A9, Transaction_Log!$A:$A, ">="&DATE(2026,3,1), Transaction_Log!$A:$A, "<="&DATE(2026,3,31)) -> 13500 | F9: =SUMIFS(Transaction_Log!$C:$C, Transaction_Log!$B:$B, $A9, Transaction_Log!$A:$A, ">="&DATE(2026,4,1), Transaction_Log!$A:$A, "<="&DATE(2026,4,30)) -> 3000 | G9: =SUMIFS(Transaction_Log!$C:$C, Transaction_Log!$B:$B, $A9, Transaction_Log!$A:$A, ">="&DATE(2026,5,1), Transaction_Log!$A:$A, "<="&DATE(2026,5,31)) -> 1500 | H9: =SUMIFS(Transaction_Log!$C:$C, Transaction_Log!$B:$B, $A9, Transaction_Log!$A:$A, ">="&DATE(2026,6,1), Transaction_Log!$A:$A, "<="&DATE(2026,6,30)) -> 0 | I9: =SUMIFS(Transaction_Log!$C:$C, Transaction_Log!$B:$B, $A9, Transaction_Log!$A:$A, ">="&DATE(2026,7,1), Transaction_Log!$A:$A, "<="&DATE(2026,7,31)) -> 0 | J9: =SUMIFS(Transaction_Log!$C:$C, Transaction_Log!$B:$B, $A9, Transaction_Log!$A:$A, ">="&DATE(2026,8,1), Transaction_Log!$A:$A, "<="&DATE(2026,8,31)) -> 0 | K9: =SUMIFS(Transaction_Log!$C:$C, Transaction_Log!$B:$B, $A9, Transaction_Log!$A:$A, ">="&DATE(2026,9,1), Transaction_Log!$A:$A, "<="&DATE(2026,9,30)) -> 0 | L9: =SUMIFS(Transaction_Log!$C:$C, Transaction_Log!$B:$B, $A9, Transaction_Log!$A:$A, ">="&DATE(2026,10,1), Transaction_Log!$A:$A, "<="&DATE(2026,10,31)) -> 0 | M9: =SUMIFS(Transaction_Log!$C:$C, Transaction_Log!$B:$B, $A9, Transaction_Log!$A:$A, ">="&DATE(2026,11,1), Transaction_Log!$A:$A, "<="&DATE(2026,11,30)) -> 0 | N9: =SUMIFS(Transaction_Log!$C:$C, Transaction_Log!$B:$B, $A9, Transaction_Log!$A:$A, ">="&DATE(2026,12,1), Transaction_Log!$A:$A, "<="&DATE(2026,12,31)) -> 0 | O9: =SUM(C9:N9) -> 18000 | P9: =+DashBoard!D8 -> 6000
A10: D 9 | B10: =VLOOKUP($A10,Owner_Master!$A:$B,2,FALSE) -> Dr G.K.Kiran Adithya | C10: =SUMIFS(Transaction_Log!$C:$C, Transaction_Log!$B:$B, $A10, Transaction_Log!$A:$A, ">="&DATE(2026,1,1), Transaction_Log!$A:$A, "<="&DATE(2026,1,31)) -> 0 | D10: =SUMIFS(Transaction_Log!$C:$C, Transaction_Log!$B:$B, $A10, Transaction_Log!$A:$A, ">="&DATE(2026,2,1), Transaction_Log!$A:$A, "<="&DATE(2026,2,28)) -> 3000 | E10: =SUMIFS(Transaction_Log!$C:$C, Transaction_Log!$B:$B, $A10, Transaction_Log!$A:$A, ">="&DATE(2026,3,1), Transaction_Log!$A:$A, "<="&DATE(2026,3,31)) -> 0 | F10: =SUMIFS(Transaction_Log!$C:$C, Transaction_Log!$B:$B, $A10, Transaction_Log!$A:$A, ">="&DATE(2026,4,1), Transaction_Log!$A:$A, "<="&DATE(2026,4,30)) -> 3000 | G10: =SUMIFS(Transaction_Log!$C:$C, Transaction_Log!$B:$B, $A10, Transaction_Log!$A:$A, ">="&DATE(2026,5,1), Transaction_Log!$A:$A, "<="&DATE(2026,5,31)) -> 0 | H10: =SUMIFS(Transaction_Log!$C:$C, Transaction_Log!$B:$B, $A10, Transaction_Log!$A:$A, ">="&DATE(2026,6,1), Transaction_Log!$A:$A, "<="&DATE(2026,6,30)) -> 0 | I10: =SUMIFS(Transaction_Log!$C:$C, Transaction_Log!$B:$B, $A10, Transaction_Log!$A:$A, ">="&DATE(2026,7,1), Transaction_Log!$A:$A, "<="&DATE(2026,7,31)) -> 0 | J10: =SUMIFS(Transaction_Log!$C:$C, Transaction_Log!$B:$B, $A10, Transaction_Log!$A:$A, ">="&DATE(2026,8,1), Transaction_Log!$A:$A, "<="&DATE(2026,8,31)) -> 0 | K10: =SUMIFS(Transaction_Log!$C:$C, Transaction_Log!$B:$B, $A10, Transaction_Log!$A:$A, ">="&DATE(2026,9,1), Transaction_Log!$A:$A, "<="&DATE(2026,9,30)) -> 0 | L10: =SUMIFS(Transaction_Log!$C:$C, Transaction_Log!$B:$B, $A10, Transaction_Log!$A:$A, ">="&DATE(2026,10,1), Transaction_Log!$A:$A, "<="&DATE(2026,10,31)) -> 0 | M10: =SUMIFS(Transaction_Log!$C:$C, Transaction_Log!$B:$B, $A10, Transaction_Log!$A:$A, ">="&DATE(2026,11,1), Transaction_Log!$A:$A, "<="&DATE(2026,11,30)) -> 0 | N10: =SUMIFS(Transaction_Log!$C:$C, Transaction_Log!$B:$B, $A10, Transaction_Log!$A:$A, ">="&DATE(2026,12,1), Transaction_Log!$A:$A, "<="&DATE(2026,12,31)) -> 0 | O10: =SUM(C10:N10) -> 6000 | P10: =+DashBoard!D9 -> 0
A11: C 10 | B11: =VLOOKUP($A11,Owner_Master!$A:$B,2,FALSE) -> R.Chetan Kumar | C11: =SUMIFS(Transaction_Log!$C:$C, Transaction_Log!$B:$B, $A11, Transaction_Log!$A:$A, ">="&DATE(2026,1,1), Transaction_Log!$A:$A, "<="&DATE(2026,1,31)) -> 1500 | D11: =SUMIFS(Transaction_Log!$C:$C, Transaction_Log!$B:$B, $A11, Transaction_Log!$A:$A, ">="&DATE(2026,2,1), Transaction_Log!$A:$A, "<="&DATE(2026,2,28)) -> 1500 | E11: =SUMIFS(Transaction_Log!$C:$C, Transaction_Log!$B:$B, $A11, Transaction_Log!$A:$A, ">="&DATE(2026,3,1), Transaction_Log!$A:$A, "<="&DATE(2026,3,31)) -> 1500 | F11: =SUMIFS(Transaction_Log!$C:$C, Transaction_Log!$B:$B, $A11, Transaction_Log!$A:$A, ">="&DATE(2026,4,1), Transaction_Log!$A:$A, "<="&DATE(2026,4,30)) -> 1500 | G11: =SUMIFS(Transaction_Log!$C:$C, Transaction_Log!$B:$B, $A11, Transaction_Log!$A:$A, ">="&DATE(2026,5,1), Transaction_Log!$A:$A, "<="&DATE(2026,5,31)) -> 1500 | H11: =SUMIFS(Transaction_Log!$C:$C, Transaction_Log!$B:$B, $A11, Transaction_Log!$A:$A, ">="&DATE(2026,6,1), Transaction_Log!$A:$A, "<="&DATE(2026,6,30)) -> 0 | I11: =SUMIFS(Transaction_Log!$C:$C, Transaction_Log!$B:$B, $A11, Transaction_Log!$A:$A, ">="&DATE(2026,7,1), Transaction_Log!$A:$A, "<="&DATE(2026,7,31)) -> 0 | J11: =SUMIFS(Transaction_Log!$C:$C, Transaction_Log!$B:$B, $A11, Transaction_Log!$A:$A, ">="&DATE(2026,8,1), Transaction_Log!$A:$A, "<="&DATE(2026,8,31)) -> 0 | K11: =SUMIFS(Transaction_Log!$C:$C, Transaction_Log!$B:$B, $A11, Transaction_Log!$A:$A, ">="&DATE(2026,9,1), Transaction_Log!$A:$A, "<="&DATE(2026,9,30)) -> 0 | L11: =SUMIFS(Transaction_Log!$C:$C, Transaction_Log!$B:$B, $A11, Transaction_Log!$A:$A, ">="&DATE(2026,10,1), Transaction_Log!$A:$A, "<="&DATE(2026,10,31)) -> 0 | M11: =SUMIFS(Transaction_Log!$C:$C, Transaction_Log!$B:$B, $A11, Transaction_Log!$A:$A, ">="&DATE(2026,11,1), Transaction_Log!$A:$A, "<="&DATE(2026,11,30)) -> 0 | N11: =SUMIFS(Transaction_Log!$C:$C, Transaction_Log!$B:$B, $A11, Transaction_Log!$A:$A, ">="&DATE(2026,12,1), Transaction_Log!$A:$A, "<="&DATE(2026,12,31)) -> 0 | O11: =SUM(C11:N11) -> 7500 | P11: =+DashBoard!D10 -> 0
A12: C 11 | B12: =VLOOKUP($A12,Owner_Master!$A:$B,2,FALSE) -> K.Eswari | C12: =SUMIFS(Transaction_Log!$C:$C, Transaction_Log!$B:$B, $A12, Transaction_Log!$A:$A, ">="&DATE(2026,1,1), Transaction_Log!$A:$A, "<="&DATE(2026,1,31)) -> 0 | D12: =SUMIFS(Transaction_Log!$C:$C, Transaction_Log!$B:$B, $A12, Transaction_Log!$A:$A, ">="&DATE(2026,2,1), Transaction_Log!$A:$A, "<="&DATE(2026,2,28)) -> 0 | E12: =SUMIFS(Transaction_Log!$C:$C, Transaction_Log!$B:$B, $A12, Transaction_Log!$A:$A, ">="&DATE(2026,3,1), Transaction_Log!$A:$A, "<="&DATE(2026,3,31)) -> 0 | F12: =SUMIFS(Transaction_Log!$C:$C, Transaction_Log!$B:$B, $A12, Transaction_Log!$A:$A, ">="&DATE(2026,4,1), Transaction_Log!$A:$A, "<="&DATE(2026,4,30)) -> 0 | G12: =SUMIFS(Transaction_Log!$C:$C, Transaction_Log!$B:$B, $A12, Transaction_Log!$A:$A, ">="&DATE(2026,5,1), Transaction_Log!$A:$A, "<="&DATE(2026,5,31)) -> 31000 | H12: =SUMIFS(Transaction_Log!$C:$C, Transaction_Log!$B:$B, $A12, Transaction_Log!$A:$A, ">="&DATE(2026,6,1), Transaction_Log!$A:$A, "<="&DATE(2026,6,30)) -> 0 | I12: =SUMIFS(Transaction_Log!$C:$C, Transaction_Log!$B:$B, $A12, Transaction_Log!$A:$A, ">="&DATE(2026,7,1), Transaction_Log!$A:$A, "<="&DATE(2026,7,31)) -> 0 | J12: =SUMIFS(Transaction_Log!$C:$C, Transaction_Log!$B:$B, $A12, Transaction_Log!$A:$A, ">="&DATE(2026,8,1), Transaction_Log!$A:$A, "<="&DATE(2026,8,31)) -> 0 | K12: =SUMIFS(Transaction_Log!$C:$C, Transaction_Log!$B:$B, $A12, Transaction_Log!$A:$A, ">="&DATE(2026,9,1), Transaction_Log!$A:$A, "<="&DATE(2026,9,30)) -> 0 | L12: =SUMIFS(Transaction_Log!$C:$C, Transaction_Log!$B:$B, $A12, Transaction_Log!$A:$A, ">="&DATE(2026,10,1), Transaction_Log!$A:$A, "<="&DATE(2026,10,31)) -> 0 | M12: =SUMIFS(Transaction_Log!$C:$C, Transaction_Log!$B:$B, $A12, Transaction_Log!$A:$A, ">="&DATE(2026,11,1), Transaction_Log!$A:$A, "<="&DATE(2026,11,30)) -> 0 | N12: =SUMIFS(Transaction_Log!$C:$C, Transaction_Log!$B:$B, $A12, Transaction_Log!$A:$A, ">="&DATE(2026,12,1), Transaction_Log!$A:$A, "<="&DATE(2026,12,31)) -> 0 | O12: =SUM(C12:N12) -> 31000 | P12: =+DashBoard!D11 -> 8000
A13: C 12 | B13: =VLOOKUP($A13,Owner_Master!$A:$B,2,FALSE) -> Selvendran Ayyaswamy | C13: =SUMIFS(Transaction_Log!$C:$C, Transaction_Log!$B:$B, $A13, Transaction_Log!$A:$A, ">="&DATE(2026,1,1), Transaction_Log!$A:$A, "<="&DATE(2026,1,31)) -> 3000 | D13: =SUMIFS(Transaction_Log!$C:$C, Transaction_Log!$B:$B, $A13, Transaction_Log!$A:$A, ">="&DATE(2026,2,1), Transaction_Log!$A:$A, "<="&DATE(2026,2,28)) -> 3000 | E13: =SUMIFS(Transaction_Log!$C:$C, Transaction_Log!$B:$B, $A13, Transaction_Log!$A:$A, ">="&DATE(2026,3,1), Transaction_Log!$A:$A, "<="&DATE(2026,3,31)) -> 0 | F13: =SUMIFS(Transaction_Log!$C:$C, Transaction_Log!$B:$B, $A13, Transaction_Log!$A:$A, ">="&DATE(2026,4,1), Transaction_Log!$A:$A, "<="&DATE(2026,4,30)) -> 3000 | G13: =SUMIFS(Transaction_Log!$C:$C, Transaction_Log!$B:$B, $A13, Transaction_Log!$A:$A, ">="&DATE(2026,5,1), Transaction_Log!$A:$A, "<="&DATE(2026,5,31)) -> 0 | H13: =SUMIFS(Transaction_Log!$C:$C, Transaction_Log!$B:$B, $A13, Transaction_Log!$A:$A, ">="&DATE(2026,6,1), Transaction_Log!$A:$A, "<="&DATE(2026,6,30)) -> 0 | I13: =SUMIFS(Transaction_Log!$C:$C, Transaction_Log!$B:$B, $A13, Transaction_Log!$A:$A, ">="&DATE(2026,7,1), Transaction_Log!$A:$A, "<="&DATE(2026,7,31)) -> 0 | J13: =SUMIFS(Transaction_Log!$C:$C, Transaction_Log!$B:$B, $A13, Transaction_Log!$A:$A, ">="&DATE(2026,8,1), Transaction_Log!$A:$A, "<="&DATE(2026,8,31)) -> 0 | K13: =SUMIFS(Transaction_Log!$C:$C, Transaction_Log!$B:$B, $A13, Transaction_Log!$A:$A, ">="&DATE(2026,9,1), Transaction_Log!$A:$A, "<="&DATE(2026,9,30)) -> 0 | L13: =SUMIFS(Transaction_Log!$C:$C, Transaction_Log!$B:$B, $A13, Transaction_Log!$A:$A, ">="&DATE(2026,10,1), Transaction_Log!$A:$A, "<="&DATE(2026,10,31)) -> 0 | M13: =SUMIFS(Transaction_Log!$C:$C, Transaction_Log!$B:$B, $A13, Transaction_Log!$A:$A, ">="&DATE(2026,11,1), Transaction_Log!$A:$A, "<="&DATE(2026,11,30)) -> 0 | N13: =SUMIFS(Transaction_Log!$C:$C, Transaction_Log!$B:$B, $A13, Transaction_Log!$A:$A, ">="&DATE(2026,12,1), Transaction_Log!$A:$A, "<="&DATE(2026,12,31)) -> 0 | O13: =SUM(C13:N13) -> 9000 | P13: =+DashBoard!D12 -> 0
A14: C 14 | B14: =VLOOKUP($A14,Owner_Master!$A:$B,2,FALSE) -> Latish Babu | C14: =SUMIFS(Transaction_Log!$C:$C, Transaction_Log!$B:$B, $A14, Transaction_Log!$A:$A, ">="&DATE(2026,1,1), Transaction_Log!$A:$A, "<="&DATE(2026,1,31)) -> 1500 | D14: =SUMIFS(Transaction_Log!$C:$C, Transaction_Log!$B:$B, $A14, Transaction_Log!$A:$A, ">="&DATE(2026,2,1), Transaction_Log!$A:$A, "<="&DATE(2026,2,28)) -> 1500 | E14: =SUMIFS(Transaction_Log!$C:$C, Transaction_Log!$B:$B, $A14, Transaction_Log!$A:$A, ">="&DATE(2026,3,1), Transaction_Log!$A:$A, "<="&DATE(2026,3,31)) -> 0 | F14: =SUMIFS(Transaction_Log!$C:$C, Transaction_Log!$B:$B, $A14, Transaction_Log!$A:$A, ">="&DATE(2026,4,1), Transaction_Log!$A:$A, "<="&DATE(2026,4,30)) -> 1500 | G14: =SUMIFS(Transaction_Log!$C:$C, Transaction_Log!$B:$B, $A14, Transaction_Log!$A:$A, ">="&DATE(2026,5,1), Transaction_Log!$A:$A, "<="&DATE(2026,5,31)) -> 1500 | H14: =SUMIFS(Transaction_Log!$C:$C, Transaction_Log!$B:$B, $A14, Transaction_Log!$A:$A, ">="&DATE(2026,6,1), Transaction_Log!$A:$A, "<="&DATE(2026,6,30)) -> 0 | I14: =SUMIFS(Transaction_Log!$C:$C, Transaction_Log!$B:$B, $A14, Transaction_Log!$A:$A, ">="&DATE(2026,7,1), Transaction_Log!$A:$A, "<="&DATE(2026,7,31)) -> 0 | J14: =SUMIFS(Transaction_Log!$C:$C, Transaction_Log!$B:$B, $A14, Transaction_Log!$A:$A, ">="&DATE(2026,8,1), Transaction_Log!$A:$A, "<="&DATE(2026,8,31)) -> 0 | K14: =SUMIFS(Transaction_Log!$C:$C, Transaction_Log!$B:$B, $A14, Transaction_Log!$A:$A, ">="&DATE(2026,9,1), Transaction_Log!$A:$A, "<="&DATE(2026,9,30)) -> 0 | L14: =SUMIFS(Transaction_Log!$C:$C, Transaction_Log!$B:$B, $A14, Transaction_Log!$A:$A, ">="&DATE(2026,10,1), Transaction_Log!$A:$A, "<="&DATE(2026,10,31)) -> 0 | M14: =SUMIFS(Transaction_Log!$C:$C, Transaction_Log!$B:$B, $A14, Transaction_Log!$A:$A, ">="&DATE(2026,11,1), Transaction_Log!$A:$A, "<="&DATE(2026,11,30)) -> 0 | N14: =SUMIFS(Transaction_Log!$C:$C, Transaction_Log!$B:$B, $A14, Transaction_Log!$A:$A, ">="&DATE(2026,12,1), Transaction_Log!$A:$A, "<="&DATE(2026,12,31)) -> 0 | O14: =SUM(C14:N14) -> 6000 | P14: =+DashBoard!D13 -> 1500
A15: C 15 | B15: =VLOOKUP($A15,Owner_Master!$A:$B,2,FALSE) -> S.Periasamy | C15: =SUMIFS(Transaction_Log!$C:$C, Transaction_Log!$B:$B, $A15, Transaction_Log!$A:$A, ">="&DATE(2026,1,1), Transaction_Log!$A:$A, "<="&DATE(2026,1,31)) -> 0 | D15: =SUMIFS(Transaction_Log!$C:$C, Transaction_Log!$B:$B, $A15, Transaction_Log!$A:$A, ">="&DATE(2026,2,1), Transaction_Log!$A:$A, "<="&DATE(2026,2,28)) -> 15500 | E15: =SUMIFS(Transaction_Log!$C:$C, Transaction_Log!$B:$B, $A15, Transaction_Log!$A:$A, ">="&DATE(2026,3,1), Transaction_Log!$A:$A, "<="&DATE(2026,3,31)) -> 0 | F15: =SUMIFS(Transaction_Log!$C:$C, Transaction_Log!$B:$B, $A15, Transaction_Log!$A:$A, ">="&DATE(2026,4,1), Transaction_Log!$A:$A, "<="&DATE(2026,4,30)) -> 0 | G15: =SUMIFS(Transaction_Log!$C:$C, Transaction_Log!$B:$B, $A15, Transaction_Log!$A:$A, ">="&DATE(2026,5,1), Transaction_Log!$A:$A, "<="&DATE(2026,5,31)) -> 9000 | H15: =SUMIFS(Transaction_Log!$C:$C, Transaction_Log!$B:$B, $A15, Transaction_Log!$A:$A, ">="&DATE(2026,6,1), Transaction_Log!$A:$A, "<="&DATE(2026,6,30)) -> 0 | I15: =SUMIFS(Transaction_Log!$C:$C, Transaction_Log!$B:$B, $A15, Transaction_Log!$A:$A, ">="&DATE(2026,7,1), Transaction_Log!$A:$A, "<="&DATE(2026,7,31)) -> 0 | J15: =SUMIFS(Transaction_Log!$C:$C, Transaction_Log!$B:$B, $A15, Transaction_Log!$A:$A, ">="&DATE(2026,8,1), Transaction_Log!$A:$A, "<="&DATE(2026,8,31)) -> 0 | K15: =SUMIFS(Transaction_Log!$C:$C, Transaction_Log!$B:$B, $A15, Transaction_Log!$A:$A, ">="&DATE(2026,9,1), Transaction_Log!$A:$A, "<="&DATE(2026,9,30)) -> 0 | L15: =SUMIFS(Transaction_Log!$C:$C, Transaction_Log!$B:$B, $A15, Transaction_Log!$A:$A, ">="&DATE(2026,10,1), Transaction_Log!$A:$A, "<="&DATE(2026,10,31)) -> 0 | M15: =SUMIFS(Transaction_Log!$C:$C, Transaction_Log!$B:$B, $A15, Transaction_Log!$A:$A, ">="&DATE(2026,11,1), Transaction_Log!$A:$A, "<="&DATE(2026,11,30)) -> 0 | N15: =SUMIFS(Transaction_Log!$C:$C, Transaction_Log!$B:$B, $A15, Transaction_Log!$A:$A, ">="&DATE(2026,12,1), Transaction_Log!$A:$A, "<="&DATE(2026,12,31)) -> 0 | O15: =SUM(C15:N15) -> 24500 | P15: =+DashBoard!D14 -> -6000
A16: C 16 | B16: =VLOOKUP($A16,Owner_Master!$A:$B,2,FALSE) -> Arunkarthick and Dr.Haripraba | C16: =SUMIFS(Transaction_Log!$C:$C, Transaction_Log!$B:$B, $A16, Transaction_Log!$A:$A, ">="&DATE(2026,1,1), Transaction_Log!$A:$A, "<="&DATE(2026,1,31)) -> 0 | D16: =SUMIFS(Transaction_Log!$C:$C, Transaction_Log!$B:$B, $A16, Transaction_Log!$A:$A, ">="&DATE(2026,2,1), Transaction_Log!$A:$A, "<="&DATE(2026,2,28)) -> 0 | E16: =SUMIFS(Transaction_Log!$C:$C, Transaction_Log!$B:$B, $A16, Transaction_Log!$A:$A, ">="&DATE(2026,3,1), Transaction_Log!$A:$A, "<="&DATE(2026,3,31)) -> 19500 | F16: =SUMIFS(Transaction_Log!$C:$C, Transaction_Log!$B:$B, $A16, Transaction_Log!$A:$A, ">="&DATE(2026,4,1), Transaction_Log!$A:$A, "<="&DATE(2026,4,30)) -> 1500 | G16: =SUMIFS(Transaction_Log!$C:$C, Transaction_Log!$B:$B, $A16, Transaction_Log!$A:$A, ">="&DATE(2026,5,1), Transaction_Log!$A:$A, "<="&DATE(2026,5,31)) -> 1500 | H16: =SUMIFS(Transaction_Log!$C:$C, Transaction_Log!$B:$B, $A16, Transaction_Log!$A:$A, ">="&DATE(2026,6,1), Transaction_Log!$A:$A, "<="&DATE(2026,6,30)) -> 0 | I16: =SUMIFS(Transaction_Log!$C:$C, Transaction_Log!$B:$B, $A16, Transaction_Log!$A:$A, ">="&DATE(2026,7,1), Transaction_Log!$A:$A, "<="&DATE(2026,7,31)) -> 0 | J16: =SUMIFS(Transaction_Log!$C:$C, Transaction_Log!$B:$B, $A16, Transaction_Log!$A:$A, ">="&DATE(2026,8,1), Transaction_Log!$A:$A, "<="&DATE(2026,8,31)) -> 0 | K16: =SUMIFS(Transaction_Log!$C:$C, Transaction_Log!$B:$B, $A16, Transaction_Log!$A:$A, ">="&DATE(2026,9,1), Transaction_Log!$A:$A, "<="&DATE(2026,9,30)) -> 0 | L16: =SUMIFS(Transaction_Log!$C:$C, Transaction_Log!$B:$B, $A16, Transaction_Log!$A:$A, ">="&DATE(2026,10,1), Transaction_Log!$A:$A, "<="&DATE(2026,10,31)) -> 0 | M16: =SUMIFS(Transaction_Log!$C:$C, Transaction_Log!$B:$B, $A16, Transaction_Log!$A:$A, ">="&DATE(2026,11,1), Transaction_Log!$A:$A, "<="&DATE(2026,11,30)) -> 0 | N16: =SUMIFS(Transaction_Log!$C:$C, Transaction_Log!$B:$B, $A16, Transaction_Log!$A:$A, ">="&DATE(2026,12,1), Transaction_Log!$A:$A, "<="&DATE(2026,12,31)) -> 0 | O16: =SUM(C16:N16) -> 22500 | P16: =+DashBoard!D15 -> 0
A17: C 18 - 19 | B17: =VLOOKUP($A17,Owner_Master!$A:$B,2,FALSE) -> Malathy Sundaram | C17: =SUMIFS(Transaction_Log!$C:$C, Transaction_Log!$B:$B, $A17, Transaction_Log!$A:$A, ">="&DATE(2026,1,1), Transaction_Log!$A:$A, "<="&DATE(2026,1,31)) -> 1500 | D17: =SUMIFS(Transaction_Log!$C:$C, Transaction_Log!$B:$B, $A17, Transaction_Log!$A:$A, ">="&DATE(2026,2,1), Transaction_Log!$A:$A, "<="&DATE(2026,2,28)) -> 1500 | E17: =SUMIFS(Transaction_Log!$C:$C, Transaction_Log!$B:$B, $A17, Transaction_Log!$A:$A, ">="&DATE(2026,3,1), Transaction_Log!$A:$A, "<="&DATE(2026,3,31)) -> 1500 | F17: =SUMIFS(Transaction_Log!$C:$C, Transaction_Log!$B:$B, $A17, Transaction_Log!$A:$A, ">="&DATE(2026,4,1), Transaction_Log!$A:$A, "<="&DATE(2026,4,30)) -> 1500 | G17: =SUMIFS(Transaction_Log!$C:$C, Transaction_Log!$B:$B, $A17, Transaction_Log!$A:$A, ">="&DATE(2026,5,1), Transaction_Log!$A:$A, "<="&DATE(2026,5,31)) -> 1500 | H17: =SUMIFS(Transaction_Log!$C:$C, Transaction_Log!$B:$B, $A17, Transaction_Log!$A:$A, ">="&DATE(2026,6,1), Transaction_Log!$A:$A, "<="&DATE(2026,6,30)) -> 0 | I17: =SUMIFS(Transaction_Log!$C:$C, Transaction_Log!$B:$B, $A17, Transaction_Log!$A:$A, ">="&DATE(2026,7,1), Transaction_Log!$A:$A, "<="&DATE(2026,7,31)) -> 0 | J17: =SUMIFS(Transaction_Log!$C:$C, Transaction_Log!$B:$B, $A17, Transaction_Log!$A:$A, ">="&DATE(2026,8,1), Transaction_Log!$A:$A, "<="&DATE(2026,8,31)) -> 0 | K17: =SUMIFS(Transaction_Log!$C:$C, Transaction_Log!$B:$B, $A17, Transaction_Log!$A:$A, ">="&DATE(2026,9,1), Transaction_Log!$A:$A, "<="&DATE(2026,9,30)) -> 0 | L17: =SUMIFS(Transaction_Log!$C:$C, Transaction_Log!$B:$B, $A17, Transaction_Log!$A:$A, ">="&DATE(2026,10,1), Transaction_Log!$A:$A, "<="&DATE(2026,10,31)) -> 0 | M17: =SUMIFS(Transaction_Log!$C:$C, Transaction_Log!$B:$B, $A17, Transaction_Log!$A:$A, ">="&DATE(2026,11,1), Transaction_Log!$A:$A, "<="&DATE(2026,11,30)) -> 0 | N17: =SUMIFS(Transaction_Log!$C:$C, Transaction_Log!$B:$B, $A17, Transaction_Log!$A:$A, ">="&DATE(2026,12,1), Transaction_Log!$A:$A, "<="&DATE(2026,12,31)) -> 0 | O17: =SUM(C17:N17) -> 7500 | P17: =+DashBoard!D16 -> 0
A18: B 20 - 21 | B18: =VLOOKUP($A18,Owner_Master!$A:$B,2,FALSE) -> M .Kalaivani Chandramohan | C18: =SUMIFS(Transaction_Log!$C:$C, Transaction_Log!$B:$B, $A18, Transaction_Log!$A:$A, ">="&DATE(2026,1,1), Transaction_Log!$A:$A, "<="&DATE(2026,1,31)) -> 1500 | D18: =SUMIFS(Transaction_Log!$C:$C, Transaction_Log!$B:$B, $A18, Transaction_Log!$A:$A, ">="&DATE(2026,2,1), Transaction_Log!$A:$A, "<="&DATE(2026,2,28)) -> 3000 | E18: =SUMIFS(Transaction_Log!$C:$C, Transaction_Log!$B:$B, $A18, Transaction_Log!$A:$A, ">="&DATE(2026,3,1), Transaction_Log!$A:$A, "<="&DATE(2026,3,31)) -> 0 | F18: =SUMIFS(Transaction_Log!$C:$C, Transaction_Log!$B:$B, $A18, Transaction_Log!$A:$A, ">="&DATE(2026,4,1), Transaction_Log!$A:$A, "<="&DATE(2026,4,30)) -> 1500 | G18: =SUMIFS(Transaction_Log!$C:$C, Transaction_Log!$B:$B, $A18, Transaction_Log!$A:$A, ">="&DATE(2026,5,1), Transaction_Log!$A:$A, "<="&DATE(2026,5,31)) -> 1500 | H18: =SUMIFS(Transaction_Log!$C:$C, Transaction_Log!$B:$B, $A18, Transaction_Log!$A:$A, ">="&DATE(2026,6,1), Transaction_Log!$A:$A, "<="&DATE(2026,6,30)) -> 0 | I18: =SUMIFS(Transaction_Log!$C:$C, Transaction_Log!$B:$B, $A18, Transaction_Log!$A:$A, ">="&DATE(2026,7,1), Transaction_Log!$A:$A, "<="&DATE(2026,7,31)) -> 0 | J18: =SUMIFS(Transaction_Log!$C:$C, Transaction_Log!$B:$B, $A18, Transaction_Log!$A:$A, ">="&DATE(2026,8,1), Transaction_Log!$A:$A, "<="&DATE(2026,8,31)) -> 0 | K18: =SUMIFS(Transaction_Log!$C:$C, Transaction_Log!$B:$B, $A18, Transaction_Log!$A:$A, ">="&DATE(2026,9,1), Transaction_Log!$A:$A, "<="&DATE(2026,9,30)) -> 0 | L18: =SUMIFS(Transaction_Log!$C:$C, Transaction_Log!$B:$B, $A18, Transaction_Log!$A:$A, ">="&DATE(2026,10,1), Transaction_Log!$A:$A, "<="&DATE(2026,10,31)) -> 0 | M18: =SUMIFS(Transaction_Log!$C:$C, Transaction_Log!$B:$B, $A18, Transaction_Log!$A:$A, ">="&DATE(2026,11,1), Transaction_Log!$A:$A, "<="&DATE(2026,11,30)) -> 0 | N18: =SUMIFS(Transaction_Log!$C:$C, Transaction_Log!$B:$B, $A18, Transaction_Log!$A:$A, ">="&DATE(2026,12,1), Transaction_Log!$A:$A, "<="&DATE(2026,12,31)) -> 0 | O18: =SUM(C18:N18) -> 7500 | P18: =+DashBoard!D17 -> 0
A19: B 22 | B19: =VLOOKUP($A19,Owner_Master!$A:$B,2,FALSE) -> N.Naveenkumar & G.Mahalakshmi | C19: =SUMIFS(Transaction_Log!$C:$C, Transaction_Log!$B:$B, $A19, Transaction_Log!$A:$A, ">="&DATE(2026,1,1), Transaction_Log!$A:$A, "<="&DATE(2026,1,31)) -> 1500 | D19: =SUMIFS(Transaction_Log!$C:$C, Transaction_Log!$B:$B, $A19, Transaction_Log!$A:$A, ">="&DATE(2026,2,1), Transaction_Log!$A:$A, "<="&DATE(2026,2,28)) -> 1500 | E19: =SUMIFS(Transaction_Log!$C:$C, Transaction_Log!$B:$B, $A19, Transaction_Log!$A:$A, ">="&DATE(2026,3,1), Transaction_Log!$A:$A, "<="&DATE(2026,3,31)) -> 1500 | F19: =SUMIFS(Transaction_Log!$C:$C, Transaction_Log!$B:$B, $A19, Transaction_Log!$A:$A, ">="&DATE(2026,4,1), Transaction_Log!$A:$A, "<="&DATE(2026,4,30)) -> 1500 | G19: =SUMIFS(Transaction_Log!$C:$C, Transaction_Log!$B:$B, $A19, Transaction_Log!$A:$A, ">="&DATE(2026,5,1), Transaction_Log!$A:$A, "<="&DATE(2026,5,31)) -> 1500 | H19: =SUMIFS(Transaction_Log!$C:$C, Transaction_Log!$B:$B, $A19, Transaction_Log!$A:$A, ">="&DATE(2026,6,1), Transaction_Log!$A:$A, "<="&DATE(2026,6,30)) -> 0 | I19: =SUMIFS(Transaction_Log!$C:$C, Transaction_Log!$B:$B, $A19, Transaction_Log!$A:$A, ">="&DATE(2026,7,1), Transaction_Log!$A:$A, "<="&DATE(2026,7,31)) -> 0 | J19: =SUMIFS(Transaction_Log!$C:$C, Transaction_Log!$B:$B, $A19, Transaction_Log!$A:$A, ">="&DATE(2026,8,1), Transaction_Log!$A:$A, "<="&DATE(2026,8,31)) -> 0 | K19: =SUMIFS(Transaction_Log!$C:$C, Transaction_Log!$B:$B, $A19, Transaction_Log!$A:$A, ">="&DATE(2026,9,1), Transaction_Log!$A:$A, "<="&DATE(2026,9,30)) -> 0 | L19: =SUMIFS(Transaction_Log!$C:$C, Transaction_Log!$B:$B, $A19, Transaction_Log!$A:$A, ">="&DATE(2026,10,1), Transaction_Log!$A:$A, "<="&DATE(2026,10,31)) -> 0 | M19: =SUMIFS(Transaction_Log!$C:$C, Transaction_Log!$B:$B, $A19, Transaction_Log!$A:$A, ">="&DATE(2026,11,1), Transaction_Log!$A:$A, "<="&DATE(2026,11,30)) -> 0 | N19: =SUMIFS(Transaction_Log!$C:$C, Transaction_Log!$B:$B, $A19, Transaction_Log!$A:$A, ">="&DATE(2026,12,1), Transaction_Log!$A:$A, "<="&DATE(2026,12,31)) -> 0 | O19: =SUM(C19:N19) -> 7500 | P19: =+DashBoard!D18 -> 3000
A20: B 23 | B20: =VLOOKUP($A20,Owner_Master!$A:$B,2,FALSE) -> S.V. Sanjeev Kumar | C20: =SUMIFS(Transaction_Log!$C:$C, Transaction_Log!$B:$B, $A20, Transaction_Log!$A:$A, ">="&DATE(2026,1,1), Transaction_Log!$A:$A, "<="&DATE(2026,1,31)) -> 1500 | D20: =SUMIFS(Transaction_Log!$C:$C, Transaction_Log!$B:$B, $A20, Transaction_Log!$A:$A, ">="&DATE(2026,2,1), Transaction_Log!$A:$A, "<="&DATE(2026,2,28)) -> 1500 | E20: =SUMIFS(Transaction_Log!$C:$C, Transaction_Log!$B:$B, $A20, Transaction_Log!$A:$A, ">="&DATE(2026,3,1), Transaction_Log!$A:$A, "<="&DATE(2026,3,31)) -> 0 | F20: =SUMIFS(Transaction_Log!$C:$C, Transaction_Log!$B:$B, $A20, Transaction_Log!$A:$A, ">="&DATE(2026,4,1), Transaction_Log!$A:$A, "<="&DATE(2026,4,30)) -> 0 | G20: =SUMIFS(Transaction_Log!$C:$C, Transaction_Log!$B:$B, $A20, Transaction_Log!$A:$A, ">="&DATE(2026,5,1), Transaction_Log!$A:$A, "<="&DATE(2026,5,31)) -> 0 | H20: =SUMIFS(Transaction_Log!$C:$C, Transaction_Log!$B:$B, $A20, Transaction_Log!$A:$A, ">="&DATE(2026,6,1), Transaction_Log!$A:$A, "<="&DATE(2026,6,30)) -> 0 | I20: =SUMIFS(Transaction_Log!$C:$C, Transaction_Log!$B:$B, $A20, Transaction_Log!$A:$A, ">="&DATE(2026,7,1), Transaction_Log!$A:$A, "<="&DATE(2026,7,31)) -> 0 | J20: =SUMIFS(Transaction_Log!$C:$C, Transaction_Log!$B:$B, $A20, Transaction_Log!$A:$A, ">="&DATE(2026,8,1), Transaction_Log!$A:$A, "<="&DATE(2026,8,31)) -> 0 | K20: =SUMIFS(Transaction_Log!$C:$C, Transaction_Log!$B:$B, $A20, Transaction_Log!$A:$A, ">="&DATE(2026,9,1), Transaction_Log!$A:$A, "<="&DATE(2026,9,30)) -> 0 | L20: =SUMIFS(Transaction_Log!$C:$C, Transaction_Log!$B:$B, $A20, Transaction_Log!$A:$A, ">="&DATE(2026,10,1), Transaction_Log!$A:$A, "<="&DATE(2026,10,31)) -> 0 | M20: =SUMIFS(Transaction_Log!$C:$C, Transaction_Log!$B:$B, $A20, Transaction_Log!$A:$A, ">="&DATE(2026,11,1), Transaction_Log!$A:$A, "<="&DATE(2026,11,30)) -> 0 | N20: =SUMIFS(Transaction_Log!$C:$C, Transaction_Log!$B:$B, $A20, Transaction_Log!$A:$A, ">="&DATE(2026,12,1), Transaction_Log!$A:$A, "<="&DATE(2026,12,31)) -> 0 | O20: =SUM(C20:N20) -> 3000 | P20: =+DashBoard!D19 -> 4500
... A54: B 72 | B54: =VLOOKUP($A54,Owner_Master!$A:$B,2,FALSE) -> Lt.Col Vimla VR (Retd) | C54: =SUMIFS(Transaction_Log!$C:$C, Transaction_Log!$B:$B, $A54, Transaction_Log!$A:$A, ">="&DATE(2026,1,1), Transaction_Log!$A:$A, "<="&DATE(2026,1,31)) -> 0 | D54: =SUMIFS(Transaction_Log!$C:$C, Transaction_Log!$B:$B, $A54, Transaction_Log!$A:$A, ">="&DATE(2026,2,1), Transaction_Log!$A:$A, "<="&DATE(2026,2,28)) -> 4500 | E54: =SUMIFS(Transaction_Log!$C:$C, Transaction_Log!$B:$B, $A54, Transaction_Log!$A:$A, ">="&DATE(2026,3,1), Transaction_Log!$A:$A, "<="&DATE(2026,3,31)) -> 0 | F54: =SUMIFS(Transaction_Log!$C:$C, Transaction_Log!$B:$B, $A54, Transaction_Log!$A:$A, ">="&DATE(2026,4,1), Transaction_Log!$A:$A, "<="&DATE(2026,4,30)) -> 0 | G54: =SUMIFS(Transaction_Log!$C:$C, Transaction_Log!$B:$B, $A54, Transaction_Log!$A:$A, ">="&DATE(2026,5,1), Transaction_Log!$A:$A, "<="&DATE(2026,5,31)) -> 4500 | H54: =SUMIFS(Transaction_Log!$C:$C, Transaction_Log!$B:$B, $A54, Transaction_Log!$A:$A, ">="&DATE(2026,6,1), Transaction_Log!$A:$A, "<="&DATE(2026,6,30)) -> 0 | I54: =SUMIFS(Transaction_Log!$C:$C, Transaction_Log!$B:$B, $A54, Transaction_Log!$A:$A, ">="&DATE(2026,7,1), Transaction_Log!$A:$A, "<="&DATE(2026,7,31)) -> 0 | J54: =SUMIFS(Transaction_Log!$C:$C, Transaction_Log!$B:$B, $A54, Transaction_Log!$A:$A, ">="&DATE(2026,8,1), Transaction_Log!$A:$A, "<="&DATE(2026,8,31)) -> 0 | K54: =SUMIFS(Transaction_Log!$C:$C, Transaction_Log!$B:$B, $A54, Transaction_Log!$A:$A, ">="&DATE(2026,9,1), Transaction_Log!$A:$A, "<="&DATE(2026,9,30)) -> 0 | L54: =SUMIFS(Transaction_Log!$C:$C, Transaction_Log!$B:$B, $A54, Transaction_Log!$A:$A, ">="&DATE(2026,10,1), Transaction_Log!$A:$A, "<="&DATE(2026,10,31)) -> 0 | M54: =SUMIFS(Transaction_Log!$C:$C, Transaction_Log!$B:$B, $A54, Transaction_Log!$A:$A, ">="&DATE(2026,11,1), Transaction_Log!$A:$A, "<="&DATE(2026,11,30)) -> 0 | N54: =SUMIFS(Transaction_Log!$C:$C, Transaction_Log!$B:$B, $A54, Transaction_Log!$A:$A, ">="&DATE(2026,12,1), Transaction_Log!$A:$A, "<="&DATE(2026,12,31)) -> 0 | O54: =SUM(C54:N54) -> 9000 | P54: =+DashBoard!D53 -> 0
A55: Total | C55: =SUM(C3:C54) -> 80500 | D55: =SUM(D3:D54) -> 147000 | E55: =SUM(E3:E54) -> 147000 | F55: =SUM(F3:F54) -> 48000 | G55: =SUM(G3:G54) -> 154500 | H55: =SUM(H3:H54) -> 0 | I55: =SUM(I3:I54) -> 0 | J55: =SUM(J3:J54) -> 0 | ... P55: =SUM(P3:P54) -> 288500

Sheet Analysis
A1: Current Status | B1: (All) | G1: Maintenance Charges - Outstanding
A3: Villa Nos | B3: Accrued Charges | C3: Total Paid | D3: _Current Status | E3: Owner | G3: Balance as of 31st December 2025 | H3: =+Owner_Master!#REF! -> #REF!
A4: B 65 | B4: 60500 | C4: 4500 | D4: 56000 | E4: =VLOOKUP(A4, Owner_Master!$A$1:$B$53, 2,FALSE()) -> K. Suseela | G4: Maintenance Charges
A5: A 36 | B5: 45500 | C5: 3000 | D5: 42500 | E5: =VLOOKUP(A5, Owner_Master!$A$1:$B$53, 2,FALSE()) -> K.Thanikai Arasu | G5: 46023 | H5: 78000
A6: B 46 | B6: 43500 | C6: 40000 | D6: 3500 | E6: =VLOOKUP(A6, Owner_Master!$A$1:$B$53, 2,FALSE()) -> Ganesan & Anitha | G6: 46054 | H6: 78000
A7: A 56 | B7: 40000 | C7: 0 | D7: 40000 | E7: =VLOOKUP(A7, Owner_Master!$A$1:$B$53, 2,FALSE()) -> Gopinath & Mrs Anitha | G7: 46082 | H7: 78000
A8: B 63 | B8: 36000 | C8: 22500 | D8: 13500 | E8: =VLOOKUP(A8, Owner_Master!$A$1:$B$53, 2,FALSE()) -> N.Rajkumar & A.Judith Mary Deepa | H8: =SUM(H3:H7) -> #REF!
A9: C 11 | B9: 35500 | C9: 0 | D9: 35500 | E9: =VLOOKUP(A9, Owner_Master!$A$1:$B$53, 2,FALSE()) -> K.Eswari
A10: A 50 | B10: 31500 | C10: 36000 | D10: -4500 | E10: =VLOOKUP(A10, Owner_Master!$A$1:$B$53, 2,FALSE()) -> S Krishnamoorthy & Dr D Champa | G10: Payment Received
A11: B 45 | B11: 24000 | C11: 22500 | D11: 1500 | E11: =VLOOKUP(A11, Owner_Master!$A$1:$B$53, 2,FALSE()) -> K. Ramji | G11: 46023 | H11: 80500
A12: B 61 | B12: 22500 | C12: 0 | D12: 22500 | E12: =VLOOKUP(A12, Owner_Master!$A$1:$B$53, 2,FALSE()) -> N.Rajkumar & A.Judith Mary Deepa | G12: 46054 | H12: 147000
A13: A 34 | B13: 22500 | C13: 0 | D13: 22500 | E13: =VLOOKUP(A13, Owner_Master!$A$1:$B$53, 2,FALSE()) -> Sudhakar & Dhanya | G13: 46082 | H13: 58500 | I13: *
A14: B 28 | B14: 21500 | C14: 0 | D14: 21500 | E14: =VLOOKUP(A14, Owner_Master!$A$1:$B$53, 2,FALSE()) -> Dr. S. Abdhul Salam | H14: =SUM(H11:H13) -> 286000
A15: D 7 | B15: 21000 | C15: 12000 | D15: 9000 | E15: =VLOOKUP(A15, Owner_Master!$A$1:$B$53, 2,FALSE()) -> Dr. P.S. Balamurugavel
A16: B 24 | B16: 21000 | C16: 0 | D16: 21000 | E16: =VLOOKUP(A16, Owner_Master!$A$1:$B$53, 2,FALSE()) -> A.M. Rajkumar & Krishnaveni | G16: Balance as of 1st April 2026 | H16: =+H8-H14 -> #REF!
A17: D 5 | B17: 19500 | C17: 0 | D17: 19500 | E17: =VLOOKUP(A17, Owner_Master!$A$1:$B$53, 2,FALSE()) -> S. Shanthi
A18: C 16 | B18: 19500 | C18: 19500 | D18: 0 | E18: =VLOOKUP(A18, Owner_Master!$A$1:$B$53, 2,FALSE()) -> Arunkarthick and Dr.Haripraba
A19: B 48 | B19: 19500 | C19: 0 | D19: 19500 | E19: =VLOOKUP(A19, Owner_Master!$A$1:$B$53, 2,FALSE()) -> Notrayan Srinivasan | G19: * Please note March 2026 remittances have not been
A20: C 15 | B20: 15500 | C20: 15500 | D20: 0 | E20: =VLOOKUP(A20, Owner_Master!$A$1:$B$53, 2,FALSE()) -> S.Periasamy | G20: fully accounted for. Waiting for March 2026 bank statement
A21: A 29 - 30 | B21: 15000 | C21: 15000 | D21: 0 | E21: =VLOOKUP(A21, Owner_Master!$A$1:$B$53, 2,FALSE()) -> Srinivasan Ramamoorthy/ Srividya Devarajan
A22: A 33 | B22: 13500 | C22: 0 | D22: 13500 | E22: =VLOOKUP(A22, Owner_Master!$A$1:$B$53, 2,FALSE()) -> Vijayaraghavan & Hema Vijayaraghavan | G22: * This also includes prepaid payments as of 26th March 2026
A23: A 38 | B23: 10500 | C23: 9000 | D23: 1500 | E23: =VLOOKUP(A23, Owner_Master!$A$1:$B$53, 2,FALSE()) -> Manikandan Kumar & Rakeshwari
A24: B 43 | B24: 10500 | C24: 4500 | D24: 6000 | E24: =VLOOKUP(A24, Owner_Master!$A$1:$B$53, 2,FALSE()) -> N.Muthu Sivasakthi & G.Meera
A25: A 54 - 55 | B25: 9000 | C25: 0 | D25: 9000
A26: B 47 | B26: 9000 | C26: 7500 | D26: 1500 | E26: =VLOOKUP(A26, Owner_Master!$A$1:$B$53, 2,FALSE()) -> Karthik Krishnan & Dr. Soniya Selvam | G26: Paid | H26: B 64
A27: B 68 | B27: 9000 | C27: 0 | D27: 9000 | E27: =VLOOKUP(A27, Owner_Master!$A$1:$B$53, 2,FALSE()) -> R.Balaji & S.Venkata Priya | G27: 392500
A28: B 70 | B28: 7500 | C28: 0 | D28: 7500 | E28: =VLOOKUP(A28, Owner_Master!$A$1:$B$53, 2,FALSE()) -> Dr P Manivannan MD & K.Kalaichelvi IRS Retd | H28: Arrears | I28: Owner
A29: D 1 | B29: 7500 | C29: 6000 | D29: 1500 | E29: =VLOOKUP(A29, Owner_Master!$A$1:$B$53, 2,FALSE()) -> D. Abhimanyu & Amrutha Abhimanyu | H29: =VLOOKUP(H26,DashBoard!$A$1:$D$53,4,FALSE()) -> 1500 | I29: =VLOOKUP(H26,Owner_Master!$A$1:$B$53,2,FALSE()) -> Thejaswini & Mahadeva Swamy
A30: B 22 | B30: 7500 | C30: 3000 | D30: 4500 | E30: =VLOOKUP(A30, Owner_Master!$A$1:$B$53, 2,FALSE()) -> N.Naveenkumar & G.Mahalakshmi
A31: A 60 | B31: 6500 | C31: 7000 | D31: -500 | E31: =VLOOKUP(A31, Owner_Master!$A$1:$B$53, 2,FALSE()) -> Maruthachlamurthi
A32: B 64 | B32: 6000 | C32: 4500 | D32: 1500 | E32: =VLOOKUP(A32, Owner_Master!$A$1:$B$53, 2,FALSE()) -> Thejaswini & Mahadeva Swamy
A33: D 3 | B33: 6000 | C33: 0 | D33: 6000 | E33: =VLOOKUP(A33, Owner_Master!$A$1:$B$53, 2,FALSE()) -> Aishwarya Anandanathan
A34: D 2 | B34: 6000 | C34: 1500 | D34: 4500 | E34: =VLOOKUP(A34, Owner_Master!$A$1:$B$53, 2,FALSE()) -> Shyamala Krishnan
A35: A 57 - 59 | B35: 6000 | C35: 0 | D35: 6000 | E35: =VLOOKUP(A35, Owner_Master!$A$1:$B$53, 2,FALSE()) -> Dr Shreesha Kumar K
A36: C 12 | B36: 6000 | C36: 6000 | D36: 0 | E36: =VLOOKUP(A36, Owner_Master!$A$1:$B$53, 2,FALSE()) -> Selvendran Ayyaswamy
A37: A 51 - 52 | B37: 6000 | C37: 0 | D37: 6000 | E37: =VLOOKUP(A37, Owner_Master!$A$1:$B$53, 2,FALSE()) -> Hari Narayan Prasad
A38: B 72 | B38: 6000 | C38: 4500 | D38: 1500 | E38: =VLOOKUP(A38, Owner_Master!$A$1:$B$53, 2,FALSE()) -> Lt.Col Vimla VR (Retd)
A39: B 69 | B39: 4500 | C39: 3000 | D39: 1500 | E39: =VLOOKUP(A39, Owner_Master!$A$1:$B$53, 2,FALSE()) -> Rajesh Babu Krishnan
A40: B 27 | B40: 4500 | C40: 3000 | D40: 1500 | E40: =VLOOKUP(A40, Owner_Master!$A$1:$B$53, 2,FALSE()) -> S.Rajeswari
A41: B 23 | B41: 4500 | C41: 3000 | D41: 1500 | E41: =VLOOKUP(A41, Owner_Master!$A$1:$B$53, 2,FALSE()) -> S.V. Sanjeev Kumar
...

Sheet __tracelight_scratchpad__
